<?xml version="1.0" ?>
<!-- =================================================================================== -->
<!-- |    This document was autogenerated by xacro from summit_xl_hl_diff_mico.urdf.xacro | -->
<!-- |    EDITING THIS FILE BY HAND IS NOT RECOMMENDED                                 | -->
<!-- =================================================================================== -->
<robot name="summit_xl_mico" xmlns:body="http://playerstage.sourceforge.net/gazebo/xmlschema/#body" xmlns:controller="http://playerstage.sourceforge.net/gazebo/xmlschema/#controller" xmlns:gazebo="http://playerstage.sourceforge.net/gazebo/xmlschema/#gz" xmlns:geom="http://playerstage.sourceforge.net/gazebo/xmlschema/#geom" xmlns:interface="http://playerstage.sourceforge.net/gazebo/xmlschema/#interface" xmlns:joint="http://playerstage.sourceforge.net/gazebo/xmlschema/#joint" xmlns:model="http://playerstage.sourceforge.net/gazebo/xmlschema/#model" xmlns:physics="http://playerstage.sourceforge.net/gazebo/xmlschema/#physics" xmlns:renderable="http://playerstage.sourceforge.net/gazebo/xmlschema/#renderable" xmlns:rendering="http://playerstage.sourceforge.net/gazebo/xmlschema/#rendering" xmlns:sensor="http://playerstage.sourceforge.net/gazebo/xmlschema/#sensor" xmlns:xacro="http://www.ros.org/wiki/xacro" xmlns:xi="http://www.w3.org/2001/XInclude">
  <!-- ***************** -->
  <!-- Imported elements -->
  <!-- ***************** -->
  <!-- First we import all posible elements defined in the urdf.xacro files. All these elements are defined as macro:xacros -->
  <!-- Import summit XL base elements -->
  <!--	<xacro:include filename="$(find summit_description)/urdf/bases/summit_xl_hl_base.urdf.xacro" />-->
  <!-- ros control plugin -->
  <!-- skid steering plugin -->
  <gazebo reference="base_footprint">
    <material>Gazebo/Green</material>
  </gazebo>
  <!-- Import summit XL wheels -->
  <!-- Wheels -->
  <!-- really is the wheel width -->
  <!-- in kg-->
  <!-- Import all available sensors -->
  <!-- This file unifies all sensors that can be used on simulation, defined as xacro:macros -->
  <!-- Axis p5512 -->
  <!-- Axis m5013 -->
  <!-- Fotonic E Series -->
  <!-- GPS -->
  <!-- Hokuyo urg04lx -->
  <!-- Hokuyo utm30lx -->
  <!-- Hokuyo ust10lx -->
  <!-- Imu -->
  <!-- Imu hector -->
  <!-- Kinect -->
  <!-- Asus Xtion PRO -->
  <!-- Xacro properties -->
  <!-- xacro:property name="M_SCALE" value="0.001"/ -->
  <!-- xacro:property name="asus_xtion_scale" value="0.001"/ -->
  <!-- Hokuyo 3d -->
  <!-- Sick s3000 -->
  <!-- Sick s300 -->
  <!-- KinectV2 -->
  <!-- Sick Tim 571 -->
  <!-- Orbbec Astra -->
  <!-- Xacro properties -->
  <!--xacro:property name="orbbec_astra_scale" value="0.015"/-->
  <!-- RGB sensor - cam -->
  <!-- IR sensor - depth -->
  <!-- Rplidar -->
  <!-- uEye CP Gige -->
  <!-- Import Mico Arm -->
  <!--	<xacro:include filename="$(find mico_description)/urdf/mico_arm.urdf.xacro" />-->
  <!-- links      		mesh_no
   base           		0
   shoulder       		1
   arm            		2
   forearm        		3
   wrist          		4
   arm_mico       		5
   arm_half1 (7dof)		6
   arm_half2 (7dof)		7
   wrist_spherical_1  8
   wrist_spherical_2  9

   hand 3 finger  		55
   hand_2finger   		56
   finger_proximal		57
   finger_distal      58 
-->
  <!-- links      		mesh_no
   base           		0
   shoulder       		1
   arm            		2
   forearm        		3
   wrist          		4
   arm_mico       		5
   arm_half1 (7dof)		6
   arm_half2 (7dof)		7
   wrist_spherical_1  8
   wrist_spherical_2  9

   hand 3 finger  		55
   hand_2finger   		56
   finger_proximal		57
   finger_distal      58 
-->
  <!-- Import all Gazebo-customization elements -->
  <!--    <xacro:include filename="$(find mico_description)/urdf/kinova.gazebo" />-->
  <!--Used for conditional arguments for setting inertial parameters
        base 0, shoulder 1, arm 2, forearm 3, wrist 4, arm_mico 5,
        arm_half1 (7dof)	6, arm_half2 (7dof) 7, wrist_spherical_1  8, wrist_spherical_2  9
        fore_arm_mico 10,
        hand 3 finger 55, hand_2finger 56, finger_proximal 57, finger_distal 58 
    -->
  <!-- ***************** -->
  <!-- Global parameters -->
  <!-- ***************** -->
  <!-- Wheel parameters -->
  <!-- x,y,z in translation from base_link to the center of the wheel -->
  <!-- 0.167 ? -->
  <!-- Flag to select the high or low quality model -->
  <!-- *************** -->
  <!-- Robots Elements -->
  <!-- *************** -->
  <!-- Here we create the robot elements using the xacro:macros imported at the beggining of this file -->
  <!-- Summit XL base -->
  <!-- Robot mechanical and motor parameters -->
  <xacro:property name="PI" value="3.1415926535897931"/>
  <xacro:property name="wheel_width" value="0.175"/>
  <!-- BASE FOOTPRINT -->
  <link name="base_footprint">
    <visual>
      <origin rpy="0 0 0" xyz="0 0 0"/>
      <geometry>
        <box size="0.001 0.001 0.001"/>
      </geometry>
    </visual>
  </link>
  <joint name="base_footprint_joint" type="fixed">
    <origin rpy="0 0 0" xyz="0 0 0.125"/>
    <!-- ${wheel_radius} property must be defined inside wheel description -->
    <parent link="base_footprint"/>
    <child link="base_link"/>
  </joint>
  <!-- BASE_LINK -->
  <link name="base_link">
    <inertial>
      <mass value="25.0"/>
      <origin xyz="0 0 0"/>
      <inertia ixx="1.391" ixy="0.004" ixz="0.0" iyy="6.853" iyz="0.0" izz="6.125"/>
    </inertial>
    <visual>
      <origin rpy="0 0 0" xyz="0 0 0"/>
      <geometry>
        <mesh filename="package://summit_description/meshes/bases/summit_xl_hl_chassis.dae"/>
      </geometry>
      <material name="darkgrey">
        <color rgba="0.1 0.1 0.1 1"/>
      </material>
    </visual>
    <collision>
      <origin rpy="0 0 0 " xyz="0 0 0"/>
      <geometry>
        <mesh filename="package://summit_description/meshes/bases/summit_xl_hl_chassis.dae"/>
      </geometry>
    </collision>
  </link>
  <!--	<xacro:summit_xl_hl_base name="summit_xl" publish_bf="true" hq="${hq}" />-->
  <!-- Gazebo ros control pluggins -->
  <gazebo>
    <plugin filename="libgazebo_ros_control.so" name="ros_control">
      <!--<robotNamespace>/summit_xl</robotNamespace>-->
      <robotParam>robot_description</robotParam>
      <controlPeriod>0.001</controlPeriod>
      <robotSimType>gazebo_ros_control/DefaultRobotHWSim</robotSimType>
    </plugin>
  </gazebo>
  <!-- Gazebo skid steering pluggins
	<xacro:skid_steering broadcastOdomTF="1"/> -->
  <!-- WHEELS -->
  <!--WHEEL TIRE -->
  <joint name="joint_front_right_wheel" type="continuous">
    <parent link="base_link"/>
    <child link="front_right_wheel"/>
    <origin rpy="0 0 0" xyz="0.285 -0.234 0.0"/>
    <axis rpy="0 0 0" xyz="0 1 0"/>
    <limit effort="100" velocity="100"/>
    <joint_properties damping="0.0" friction="0.0"/>
  </joint>
  <link name="front_right_wheel">
    <visual>
      <!-- HIGH RESOLUTION WHEELS -->
      <origin rpy="0 0 0" xyz="0 0 0"/>
      <geometry>
        <mesh filename="package://summit_description/meshes/wheels/rubber_wheel_right.dae"/>
      </geometry>
      <!-- LOW RESOLUTION WHEELS -->
    </visual>
    <collision>
      <origin rpy="1.57079632679 0 0" xyz="0 0 0"/>
      <geometry>
        <cylinder length="0.14" radius="0.125"/>
      </geometry>
    </collision>
    <inertial>
      <mass value="6.5"/>
      <origin xyz="0 0 0"/>
      <inertia ixx="0.0360072916667" ixy="0" ixz="0" iyy="0.05078125" iyz="0" izz="0.0360072916667"/>
    </inertial>
  </link>
  <!-- Transmission is important to link the joints and the controller (see summit_xl_control/config/summit_xl_control.yaml)-->
  <transmission name="front_right_wheel_joint_trans">
    <type>transmission_interface/SimpleTransmission</type>
    <joint name="joint_front_right_wheel">
      <hardwareInterface>VelocityJointInterface</hardwareInterface>
    </joint>
    <actuator name="front_right_wheel_joint_motor">
      <mechanicalReduction>1</mechanicalReduction>
      <motorTorqueConstant>20</motorTorqueConstant>
    </actuator>
  </transmission>
  <gazebo reference="front_right_wheel">
    <mu1 value="1.0"/>
    <mu2 value="1.0"/>
    <kp value="10000000.0"/>
    <kd value="1.0"/>
    <fdir1 value="1 0 0"/>
    <turnGravityOff>false</turnGravityOff>
  </gazebo>
  <!--WHEEL TIRE -->
  <joint name="joint_front_left_wheel" type="continuous">
    <parent link="base_link"/>
    <child link="front_left_wheel"/>
    <origin rpy="0 0 0" xyz="0.285 0.234 0.0"/>
    <axis rpy="0 0 0" xyz="0 1 0"/>
    <limit effort="100" velocity="100"/>
    <joint_properties damping="0.0" friction="0.0"/>
  </joint>
  <link name="front_left_wheel">
    <visual>
      <!-- HIGH RESOLUTION WHEELS -->
      <origin rpy="0 0 0" xyz="0 0 0"/>
      <geometry>
        <mesh filename="package://summit_description/meshes/wheels/rubber_wheel_left.dae"/>
      </geometry>
      <!-- LOW RESOLUTION WHEELS -->
    </visual>
    <collision>
      <origin rpy="1.57079632679 0 0" xyz="0 0 0"/>
      <geometry>
        <cylinder length="0.14" radius="0.125"/>
      </geometry>
    </collision>
    <inertial>
      <mass value="6.5"/>
      <origin xyz="0 0 0"/>
      <inertia ixx="0.0360072916667" ixy="0" ixz="0" iyy="0.05078125" iyz="0" izz="0.0360072916667"/>
    </inertial>
  </link>
  <!-- Transmission is important to link the joints and the controller (see summit_xl_control/config/summit_xl_control.yaml)-->
  <transmission name="front_left_wheel_joint_trans">
    <type>transmission_interface/SimpleTransmission</type>
    <joint name="joint_front_left_wheel">
      <hardwareInterface>VelocityJointInterface</hardwareInterface>
    </joint>
    <actuator name="front_left_wheel_joint_motor">
      <mechanicalReduction>1</mechanicalReduction>
      <motorTorqueConstant>20</motorTorqueConstant>
    </actuator>
  </transmission>
  <gazebo reference="front_left_wheel">
    <mu1 value="1.0"/>
    <mu2 value="1.0"/>
    <kp value="10000000.0"/>
    <kd value="1.0"/>
    <fdir1 value="1 0 0"/>
    <turnGravityOff>false</turnGravityOff>
  </gazebo>
  <!--WHEEL TIRE -->
  <joint name="joint_back_left_wheel" type="continuous">
    <parent link="base_link"/>
    <child link="back_left_wheel"/>
    <origin rpy="0 0 0" xyz="-0.285 0.234 0.0"/>
    <axis rpy="0 0 0" xyz="0 1 0"/>
    <limit effort="100" velocity="100"/>
    <joint_properties damping="0.0" friction="0.0"/>
  </joint>
  <link name="back_left_wheel">
    <visual>
      <!-- HIGH RESOLUTION WHEELS -->
      <origin rpy="0 0 0" xyz="0 0 0"/>
      <geometry>
        <mesh filename="package://summit_description/meshes/wheels/rubber_wheel_left.dae"/>
      </geometry>
      <!-- LOW RESOLUTION WHEELS -->
    </visual>
    <collision>
      <origin rpy="1.57079632679 0 0" xyz="0 0 0"/>
      <geometry>
        <cylinder length="0.14" radius="0.125"/>
      </geometry>
    </collision>
    <inertial>
      <mass value="6.5"/>
      <origin xyz="0 0 0"/>
      <inertia ixx="0.0360072916667" ixy="0" ixz="0" iyy="0.05078125" iyz="0" izz="0.0360072916667"/>
    </inertial>
  </link>
  <!-- Transmission is important to link the joints and the controller (see summit_xl_control/config/summit_xl_control.yaml)-->
  <transmission name="back_left_wheel_joint_trans">
    <type>transmission_interface/SimpleTransmission</type>
    <joint name="joint_back_left_wheel">
      <hardwareInterface>VelocityJointInterface</hardwareInterface>
    </joint>
    <actuator name="back_left_wheel_joint_motor">
      <mechanicalReduction>1</mechanicalReduction>
      <motorTorqueConstant>20</motorTorqueConstant>
    </actuator>
  </transmission>
  <gazebo reference="back_left_wheel">
    <mu1 value="1.0"/>
    <mu2 value="1.0"/>
    <kp value="10000000.0"/>
    <kd value="1.0"/>
    <fdir1 value="1 0 0"/>
    <turnGravityOff>false</turnGravityOff>
  </gazebo>
  <!--WHEEL TIRE -->
  <joint name="joint_back_right_wheel" type="continuous">
    <parent link="base_link"/>
    <child link="back_right_wheel"/>
    <origin rpy="0 0 0" xyz="-0.285 -0.234 0.0"/>
    <axis rpy="0 0 0" xyz="0 1 0"/>
    <limit effort="100" velocity="100"/>
    <joint_properties damping="0.0" friction="0.0"/>
  </joint>
  <link name="back_right_wheel">
    <visual>
      <!-- HIGH RESOLUTION WHEELS -->
      <origin rpy="0 0 0" xyz="0 0 0"/>
      <geometry>
        <mesh filename="package://summit_description/meshes/wheels/rubber_wheel_right.dae"/>
      </geometry>
      <!-- LOW RESOLUTION WHEELS -->
    </visual>
    <collision>
      <origin rpy="1.57079632679 0 0" xyz="0 0 0"/>
      <geometry>
        <cylinder length="0.14" radius="0.125"/>
      </geometry>
    </collision>
    <inertial>
      <mass value="6.5"/>
      <origin xyz="0 0 0"/>
      <inertia ixx="0.0360072916667" ixy="0" ixz="0" iyy="0.05078125" iyz="0" izz="0.0360072916667"/>
    </inertial>
  </link>
  <!-- Transmission is important to link the joints and the controller (see summit_xl_control/config/summit_xl_control.yaml)-->
  <transmission name="back_right_wheel_joint_trans">
    <type>transmission_interface/SimpleTransmission</type>
    <joint name="joint_back_right_wheel">
      <hardwareInterface>VelocityJointInterface</hardwareInterface>
    </joint>
    <actuator name="back_right_wheel_joint_motor">
      <mechanicalReduction>1</mechanicalReduction>
      <motorTorqueConstant>20</motorTorqueConstant>
    </actuator>
  </transmission>
  <gazebo reference="back_right_wheel">
    <mu1 value="1.0"/>
    <mu2 value="1.0"/>
    <kp value="10000000.0"/>
    <kd value="1.0"/>
    <fdir1 value="1 0 0"/>
    <turnGravityOff>false</turnGravityOff>
  </gazebo>
  <!-- ARM KINOVA MICO2 -->
  <link name="root"/>
  <joint name="connect_root_and_summit" type="fixed">
    <child link="root"/>
    <parent link="base_link"/>
    <origin rpy="0 0.261799387799 0" xyz="0.19 0 0.17"/>
  </joint>
  <link name="mico_link_base">
    <visual>
      <geometry>
        <mesh filename="package://mico_description/meshes/base.dae"/>
      </geometry>
      <material name="carbon_fiber">
        <color rgba="0.792156862745098 0.819607843137255 0.933333333333333 1"/>
      </material>
    </visual>
    <!-- Adding ring to the model -->
    <collision>
      <geometry>
        <mesh filename="package://mico_description/meshes/base.dae"/>
      </geometry>
    </collision>
    <!-- base = 0 -->
    <inertial>
      <mass value="0.46784"/>
      <origin rpy="0 0 0" xyz="0 0 0.1255"/>
      <!-- z Axis -->
      <inertia ixx="0.000951270861568" ixy="0" ixz="0" iyy="0.000951270861568" iyz="0" izz="0.000374272"/>
      <!-- y Axis -->
      <!-- x Axis -->
    </inertial>
    <!-- shoulder = 1 -->
    <!-- arm = 2-->
    <!-- forearm = 3 -->
    <!-- wrist = 4 -->
    <!--arm_mico       		5 -->
    <!--   arm_half1 (7dof)		6 -->
    <!--   arm_half2 (7dof)		7 -->
    <!--   wrist_spherical_1  8 -->
    <!--   wrist_spherical_2  9 -->
    <!--   forearm_mico  10 -->
    <!-- hand 3 finger = 55 -->
    <!-- hand 2 finger = 56 -->
    <!-- finger_proximal = 57 -->
    <!-- finger_distal = 58 -->
  </link>
  <joint name="mico_joint_base" type="fixed">
    <parent link="root"/>
    <child link="mico_link_base"/>
    <axis xyz="0 0 0"/>
    <limit effort="2000" lower="0" upper="0" velocity="1"/>
    <origin rpy="0 0 0" xyz="0 0 0"/>
    <dynamics damping="0.0" friction="0.0"/>
  </joint>
  <link name="mico_link_1">
    <visual>
      <geometry>
        <mesh filename="package://mico_description/meshes/shoulder.dae"/>
      </geometry>
      <material name="carbon_fiber">
        <color rgba="0.792156862745098 0.819607843137255 0.933333333333333 1"/>
      </material>
    </visual>
    <!-- Adding ring to the model -->
    <visual>
      <geometry>
        <mesh filename="package://mico_description/meshes/ring_big.STL"/>
      </geometry>
    </visual>
    <collision>
      <geometry>
        <mesh filename="package://mico_description/meshes/shoulder.dae"/>
      </geometry>
    </collision>
    <!-- base = 0 -->
    <!-- shoulder = 1 -->
    <inertial>
      <mass value="0.7477"/>
      <origin xyz="0 -0.002 -0.0605"/>
      <!-- z Axis -->
      <inertia ixx="0.00152031725204" ixy="0" ixz="0" iyy="0.00152031725204" iyz="0" izz="0.00059816"/>
      <!-- y Axis -->
      <!-- x Axis -->
    </inertial>
    <!-- arm = 2-->
    <!-- forearm = 3 -->
    <!-- wrist = 4 -->
    <!--arm_mico       		5 -->
    <!--   arm_half1 (7dof)		6 -->
    <!--   arm_half2 (7dof)		7 -->
    <!--   wrist_spherical_1  8 -->
    <!--   wrist_spherical_2  9 -->
    <!--   forearm_mico  10 -->
    <!-- hand 3 finger = 55 -->
    <!-- hand 2 finger = 56 -->
    <!-- finger_proximal = 57 -->
    <!-- finger_distal = 58 -->
  </link>
  <joint name="mico_joint_1" type="continuous">
    <parent link="mico_link_base"/>
    <child link="mico_link_1"/>
    <axis xyz="0 0 1"/>
    <limit effort="2000" lower="-6.28318530718" upper="6.28318530718" velocity="1"/>
    <origin rpy="0 3.14159265359 0" xyz="0 0 0.15675"/>
    <dynamics damping="0.0" friction="0.0"/>
  </joint>
  <transmission name="mico_joint_1_trans">
    <type>transmission_interface/SimpleTransmission</type>
    <joint name="mico_joint_1">
      <hardwareInterface>EffortJointInterface</hardwareInterface>
    </joint>
    <actuator name="mico_joint_1_actuator">
      <hardwareInterface>EffortJointInterface</hardwareInterface>
      <mechanicalReduction>160</mechanicalReduction>
    </actuator>
  </transmission>
  <link name="mico_link_2">
    <visual>
      <geometry>
        <mesh filename="package://mico_description/meshes/arm_mico.dae"/>
      </geometry>
      <material name="carbon_fiber">
        <color rgba="0.792156862745098 0.819607843137255 0.933333333333333 1"/>
      </material>
    </visual>
    <!-- Adding ring to the model -->
    <visual>
      <geometry>
        <mesh filename="package://mico_description/meshes/ring_big.STL"/>
      </geometry>
    </visual>
    <collision>
      <geometry>
        <mesh filename="package://mico_description/meshes/arm_mico.dae"/>
      </geometry>
    </collision>
    <!-- base = 0 -->
    <!-- shoulder = 1 -->
    <!-- arm = 2-->
    <!-- forearm = 3 -->
    <!-- wrist = 4 -->
    <!--arm_mico       		5 -->
    <inertial>
      <mass value="0.85968"/>
      <origin xyz="0 -0.145  -0.0076"/>
      <!-- z Axis -->
      <!-- y Axis -->
      <inertia ixx="0.00467090931629" ixy="0" ixz="0" iyy="0.000386856" iyz="0" izz="0.00467090931629"/>
      <!-- x Axis -->
    </inertial>
    <!--   arm_half1 (7dof)		6 -->
    <!--   arm_half2 (7dof)		7 -->
    <!--   wrist_spherical_1  8 -->
    <!--   wrist_spherical_2  9 -->
    <!--   forearm_mico  10 -->
    <!-- hand 3 finger = 55 -->
    <!-- hand 2 finger = 56 -->
    <!-- finger_proximal = 57 -->
    <!-- finger_distal = 58 -->
  </link>
  <joint name="mico_joint_2" type="revolute">
    <parent link="mico_link_1"/>
    <child link="mico_link_2"/>
    <axis xyz="0 0 1"/>
    <limit effort="2000" lower="0.523598775598" upper="5.75958653158" velocity="1"/>
    <origin rpy="-1.57079632679 0 3.14159265359" xyz="0 0.0016 -0.11875"/>
    <dynamics damping="0.0" friction="0.0"/>
  </joint>
  <transmission name="mico_joint_2_trans">
    <type>transmission_interface/SimpleTransmission</type>
    <joint name="mico_joint_2">
      <hardwareInterface>EffortJointInterface</hardwareInterface>
    </joint>
    <actuator name="mico_joint_2_actuator">
      <hardwareInterface>EffortJointInterface</hardwareInterface>
      <mechanicalReduction>160</mechanicalReduction>
    </actuator>
  </transmission>
  <link name="mico_link_3">
    <visual>
      <geometry>
        <mesh filename="package://mico_description/meshes/forearm_mico.dae"/>
      </geometry>
      <material name="carbon_fiber">
        <color rgba="0.792156862745098 0.819607843137255 0.933333333333333 1"/>
      </material>
    </visual>
    <!-- Adding ring to the model -->
    <visual>
      <geometry>
        <mesh filename="package://mico_description/meshes/ring_big.STL"/>
      </geometry>
    </visual>
    <collision>
      <geometry>
        <mesh filename="package://mico_description/meshes/forearm_mico.dae"/>
      </geometry>
    </collision>
    <!-- base = 0 -->
    <!-- shoulder = 1 -->
    <!-- arm = 2-->
    <!-- forearm = 3 -->
    <!-- wrist = 4 -->
    <!--arm_mico       		5 -->
    <!--   arm_half1 (7dof)		6 -->
    <!--   arm_half2 (7dof)		7 -->
    <!--   wrist_spherical_1  8 -->
    <!--   wrist_spherical_2  9 -->
    <!--   forearm_mico  10 -->
    <inertial>
      <mass value="0.606"/>
      <origin xyz="0 0.0463 -0.0065"/>
      <!-- z Axis -->
      <!-- y Axis -->
      <inertia ixx="0.0003837984648" ixy="0" ixz="0" iyy="0.0001212" iyz="0" izz="0.0003837984648"/>
      <!-- x Axis -->
    </inertial>
    <!-- hand 3 finger = 55 -->
    <!-- hand 2 finger = 56 -->
    <!-- finger_proximal = 57 -->
    <!-- finger_distal = 58 -->
  </link>
  <joint name="mico_joint_3" type="revolute">
    <parent link="mico_link_2"/>
    <child link="mico_link_3"/>
    <axis xyz="0 0 1"/>
    <limit effort="2000" lower="0.523598775598" upper="5.75958653158" velocity="1"/>
    <origin rpy="0 3.14159265359 0" xyz="0 -0.290 0"/>
    <dynamics damping="0.0" friction="0.0"/>
  </joint>
  <transmission name="mico_joint_3_trans">
    <type>transmission_interface/SimpleTransmission</type>
    <joint name="mico_joint_3">
      <hardwareInterface>EffortJointInterface</hardwareInterface>
    </joint>
    <actuator name="mico_joint_3_actuator">
      <hardwareInterface>EffortJointInterface</hardwareInterface>
      <mechanicalReduction>160</mechanicalReduction>
    </actuator>
  </transmission>
  <link name="mico_link_4">
    <visual>
      <geometry>
        <mesh filename="package://mico_description/meshes/wrist.dae"/>
      </geometry>
      <material name="carbon_fiber">
        <color rgba="0.792156862745098 0.819607843137255 0.933333333333333 1"/>
      </material>
    </visual>
    <!-- Adding ring to the model -->
    <visual>
      <geometry>
        <mesh filename="package://mico_description/meshes/ring_small.STL"/>
      </geometry>
    </visual>
    <collision>
      <geometry>
        <mesh filename="package://mico_description/meshes/wrist.dae"/>
      </geometry>
    </collision>
    <!-- base = 0 -->
    <!-- shoulder = 1 -->
    <!-- arm = 2-->
    <!-- forearm = 3 -->
    <!-- wrist = 4 -->
    <inertial>
      <mass value="0.1785"/>
      <origin xyz="0 -0.037 -0.0642"/>
      <!-- z Axis -->
      <inertia ixx="7.73496906e-05" ixy="0" ixz="0" iyy="7.73496906e-05" iyz="0" izz="0.0001428"/>
      <!-- y Axis -->
      <!-- x Axis -->
    </inertial>
    <!--arm_mico       		5 -->
    <!--   arm_half1 (7dof)		6 -->
    <!--   arm_half2 (7dof)		7 -->
    <!--   wrist_spherical_1  8 -->
    <!--   wrist_spherical_2  9 -->
    <!--   forearm_mico  10 -->
    <!-- hand 3 finger = 55 -->
    <!-- hand 2 finger = 56 -->
    <!-- finger_proximal = 57 -->
    <!-- finger_distal = 58 -->
  </link>
  <joint name="mico_joint_4" type="continuous">
    <parent link="mico_link_3"/>
    <child link="mico_link_4"/>
    <axis xyz="0 0 1"/>
    <limit effort="2000" lower="-6.28318530718" upper="6.28318530718" velocity="1"/>
    <origin rpy="-1.57079632679 0 3.14159265359" xyz="0 0.1231 -0.0086"/>
    <dynamics damping="0.0" friction="0.0"/>
  </joint>
  <transmission name="mico_joint_4_trans">
    <type>transmission_interface/SimpleTransmission</type>
    <joint name="mico_joint_4">
      <hardwareInterface>EffortJointInterface</hardwareInterface>
    </joint>
    <actuator name="mico_joint_4_actuator">
      <hardwareInterface>EffortJointInterface</hardwareInterface>
      <mechanicalReduction>160</mechanicalReduction>
    </actuator>
  </transmission>
  <link name="mico_link_5">
    <visual>
      <geometry>
        <mesh filename="package://mico_description/meshes/wrist.dae"/>
      </geometry>
      <material name="carbon_fiber">
        <color rgba="0.792156862745098 0.819607843137255 0.933333333333333 1"/>
      </material>
    </visual>
    <!-- Adding ring to the model -->
    <visual>
      <geometry>
        <mesh filename="package://mico_description/meshes/ring_small.STL"/>
      </geometry>
    </visual>
    <collision>
      <geometry>
        <mesh filename="package://mico_description/meshes/wrist.dae"/>
      </geometry>
    </collision>
    <!-- base = 0 -->
    <!-- shoulder = 1 -->
    <!-- arm = 2-->
    <!-- forearm = 3 -->
    <!-- wrist = 4 -->
    <inertial>
      <mass value="0.1785"/>
      <origin xyz="0 -0.037 -0.0642"/>
      <!-- z Axis -->
      <inertia ixx="7.73496906e-05" ixy="0" ixz="0" iyy="7.73496906e-05" iyz="0" izz="0.0001428"/>
      <!-- y Axis -->
      <!-- x Axis -->
    </inertial>
    <!--arm_mico       		5 -->
    <!--   arm_half1 (7dof)		6 -->
    <!--   arm_half2 (7dof)		7 -->
    <!--   wrist_spherical_1  8 -->
    <!--   wrist_spherical_2  9 -->
    <!--   forearm_mico  10 -->
    <!-- hand 3 finger = 55 -->
    <!-- hand 2 finger = 56 -->
    <!-- finger_proximal = 57 -->
    <!-- finger_distal = 58 -->
  </link>
  <joint name="mico_joint_5" type="continuous">
    <parent link="mico_link_4"/>
    <child link="mico_link_5"/>
    <axis xyz="0 0 1"/>
    <limit effort="2000" lower="-6.28318530718" upper="6.28318530718" velocity="1"/>
    <origin rpy="1.0471975512 0 3.14159265359" xyz="0 -0.03703 -0.06414"/>
    <dynamics damping="0.0" friction="0.0"/>
  </joint>
  <transmission name="mico_joint_5_trans">
    <type>transmission_interface/SimpleTransmission</type>
    <joint name="mico_joint_5">
      <hardwareInterface>EffortJointInterface</hardwareInterface>
    </joint>
    <actuator name="mico_joint_5_actuator">
      <hardwareInterface>EffortJointInterface</hardwareInterface>
      <mechanicalReduction>160</mechanicalReduction>
    </actuator>
  </transmission>
  <link name="mico_link_6">
    <visual>
      <geometry>
        <mesh filename="package://mico_description/meshes/hand_2finger.dae"/>
      </geometry>
      <material name="carbon_fiber">
        <color rgba="0.792156862745098 0.819607843137255 0.933333333333333 1"/>
      </material>
    </visual>
    <!-- Adding ring to the model -->
    <visual>
      <geometry>
        <mesh filename="package://mico_description/meshes/ring_small.STL"/>
      </geometry>
    </visual>
    <collision>
      <geometry>
        <mesh filename="package://mico_description/meshes/hand_2finger.dae"/>
      </geometry>
    </collision>
    <!-- base = 0 -->
    <!-- shoulder = 1 -->
    <!-- arm = 2-->
    <!-- forearm = 3 -->
    <!-- wrist = 4 -->
    <!--arm_mico       		5 -->
    <!--   arm_half1 (7dof)		6 -->
    <!--   arm_half2 (7dof)		7 -->
    <!--   wrist_spherical_1  8 -->
    <!--   wrist_spherical_2  9 -->
    <!--   forearm_mico  10 -->
    <!-- hand 3 finger = 55 -->
    <!-- hand 2 finger = 56 -->
    <inertial>
      <mass value="0.78"/>
      <origin xyz="0 0 -0.06"/>
      <!-- z Axis -->
      <inertia ixx="0.000370498518" ixy="0" ixz="0" iyy="0.000370498518" iyz="0" izz="0.000624"/>
      <!-- y Axis -->
      <!-- x Axis -->
    </inertial>
    <!-- finger_proximal = 57 -->
    <!-- finger_distal = 58 -->
  </link>
  <joint name="mico_joint_6" type="continuous">
    <parent link="mico_link_5"/>
    <child link="mico_link_6"/>
    <axis xyz="0 0 1"/>
    <limit effort="2000" lower="-6.28318530718" upper="6.28318530718" velocity="1"/>
    <origin rpy="1.0471975512 0 3.14159265359" xyz="0 -0.03703 -0.06414"/>
    <dynamics damping="0.0" friction="0.0"/>
  </joint>
  <transmission name="mico_joint_6_trans">
    <type>transmission_interface/SimpleTransmission</type>
    <joint name="mico_joint_6">
      <hardwareInterface>EffortJointInterface</hardwareInterface>
    </joint>
    <actuator name="mico_joint_6_actuator">
      <hardwareInterface>EffortJointInterface</hardwareInterface>
      <mechanicalReduction>160</mechanicalReduction>
    </actuator>
  </transmission>
  <link name="mico_end_effector">
    <visual>
      <geometry>
        <box size="0 0 0"/>
      </geometry>
    </visual>
    <collision>
      <geometry>
        <box size="0 0 0"/>
      </geometry>
    </collision>
  </link>
  <joint name="mico_joint_end_effector" type="fixed">
    <parent link="mico_link_6"/>
    <child link="mico_end_effector"/>
    <axis xyz="0 0 0"/>
    <limit effort="2000" lower="0" upper="0" velocity="1"/>
    <origin rpy="3.14159265359 0 0" xyz="0 0 -0.1600"/>
  </joint>
  <!-- finger1 Rot := Ry((1/2)*Pi) . Rx(Pi) . Rz(-52.8*((1/180)*Pi)) -->
  <link name="mico_link_finger_1">
    <visual>
      <geometry>
        <mesh filename="package://mico_description/meshes/finger_proximal.dae"/>
      </geometry>
      <material name="carbon_fiber">
        <color rgba="0.792156862745098 0.819607843137255 0.933333333333333 1"/>
      </material>
    </visual>
    <!-- Adding ring to the model -->
    <collision>
      <geometry>
        <mesh filename="package://mico_description/meshes/finger_proximal.dae"/>
      </geometry>
    </collision>
    <!-- base = 0 -->
    <!-- shoulder = 1 -->
    <!-- arm = 2-->
    <!-- forearm = 3 -->
    <!-- wrist = 4 -->
    <!--arm_mico       		5 -->
    <!--   arm_half1 (7dof)		6 -->
    <!--   arm_half2 (7dof)		7 -->
    <!--   wrist_spherical_1  8 -->
    <!--   wrist_spherical_2  9 -->
    <!--   forearm_mico  10 -->
    <!-- hand 3 finger = 55 -->
    <!-- hand 2 finger = 56 -->
    <!-- finger_proximal = 57 -->
    <inertial>
      <mass value="0.01"/>
      <origin xyz="0.022 0 0"/>
      <!-- z Axis -->
      <inertia ixx="7.8999684e-07" ixy="0" ixz="0" iyy="7.8999684e-07" iyz="0" izz="8e-08"/>
      <!-- y Axis -->
      <!-- x Axis -->
    </inertial>
    <!-- finger_distal = 58 -->
  </link>
  <joint name="mico_joint_finger_1" type="revolute">
    <parent link="mico_link_6"/>
    <child link="mico_link_finger_1"/>
    <axis xyz="0 0 1"/>
    <origin rpy="-1.570796327 .649262481663582 1.57079632679490" xyz="-0.0025 0.03095 -0.11482"/>
    <limit effort="2000" lower="0" upper="2" velocity="1"/>
  </joint>
  <transmission name="mico_joint_finger_1_trans">
    <type>transmission_interface/SimpleTransmission</type>
    <joint name="mico_joint_finger_1">
      <hardwareInterface>EffortJointInterface</hardwareInterface>
    </joint>
    <actuator name="mico_joint_finger_1_actuator">
      <hardwareInterface>EffortJointInterface</hardwareInterface>
      <mechanicalReduction>1</mechanicalReduction>
    </actuator>
  </transmission>
  <link name="mico_link_finger_tip_1">
    <visual>
      <geometry>
        <mesh filename="package://mico_description/meshes/finger_distal.dae"/>
      </geometry>
      <material name="carbon_fiber">
        <color rgba="0.792156862745098 0.819607843137255 0.933333333333333 1"/>
      </material>
    </visual>
    <!-- Adding ring to the model -->
    <collision>
      <geometry>
        <mesh filename="package://mico_description/meshes/finger_distal.dae"/>
      </geometry>
    </collision>
    <!-- base = 0 -->
    <!-- shoulder = 1 -->
    <!-- arm = 2-->
    <!-- forearm = 3 -->
    <!-- wrist = 4 -->
    <!--arm_mico       		5 -->
    <!--   arm_half1 (7dof)		6 -->
    <!--   arm_half2 (7dof)		7 -->
    <!--   wrist_spherical_1  8 -->
    <!--   wrist_spherical_2  9 -->
    <!--   forearm_mico  10 -->
    <!-- hand 3 finger = 55 -->
    <!-- hand 2 finger = 56 -->
    <!-- finger_proximal = 57 -->
    <!-- finger_distal = 58 -->
    <inertial>
      <mass value="0.01"/>
      <origin xyz="0.022 0 0"/>
      <!-- z Axis -->
      <inertia ixx="7.8999684e-07" ixy="0" ixz="0" iyy="7.8999684e-07" iyz="0" izz="8e-08"/>
      <!-- y Axis -->
      <!-- x Axis -->
    </inertial>
  </link>
  <joint name="mico_joint_finger_tip_1" type="fixed">
    <parent link="mico_link_finger_1"/>
    <child link="mico_link_finger_tip_1"/>
    <axis xyz="0 0 1"/>
    <origin rpy="0 0 0" xyz="0.044 -0.003 0"/>
    <limit effort="2000" lower="0" upper="2" velocity="1"/>
  </joint>
  <!-- finger2 Rot := Ry((1/2)*Pi) . Rz(-52.8*((1/180)*Pi))  -->
  <link name="mico_link_finger_2">
    <visual>
      <geometry>
        <mesh filename="package://mico_description/meshes/finger_proximal.dae"/>
      </geometry>
      <material name="carbon_fiber">
        <color rgba="0.792156862745098 0.819607843137255 0.933333333333333 1"/>
      </material>
    </visual>
    <!-- Adding ring to the model -->
    <collision>
      <geometry>
        <mesh filename="package://mico_description/meshes/finger_proximal.dae"/>
      </geometry>
    </collision>
    <!-- base = 0 -->
    <!-- shoulder = 1 -->
    <!-- arm = 2-->
    <!-- forearm = 3 -->
    <!-- wrist = 4 -->
    <!--arm_mico       		5 -->
    <!--   arm_half1 (7dof)		6 -->
    <!--   arm_half2 (7dof)		7 -->
    <!--   wrist_spherical_1  8 -->
    <!--   wrist_spherical_2  9 -->
    <!--   forearm_mico  10 -->
    <!-- hand 3 finger = 55 -->
    <!-- hand 2 finger = 56 -->
    <!-- finger_proximal = 57 -->
    <inertial>
      <mass value="0.01"/>
      <origin xyz="0.022 0 0"/>
      <!-- z Axis -->
      <inertia ixx="7.8999684e-07" ixy="0" ixz="0" iyy="7.8999684e-07" iyz="0" izz="8e-08"/>
      <!-- y Axis -->
      <!-- x Axis -->
    </inertial>
    <!-- finger_distal = 58 -->
  </link>
  <joint name="mico_joint_finger_2" type="revolute">
    <parent link="mico_link_6"/>
    <child link="mico_link_finger_2"/>
    <axis xyz="0 0 1"/>
    <origin rpy="-1.570796327 .649262481663582 -1.57079632679490" xyz="-0.0025 -0.03095 -0.11482"/>
    <limit effort="2000" lower="0" upper="2" velocity="1"/>
  </joint>
  <transmission name="mico_joint_finger_2_trans">
    <type>transmission_interface/SimpleTransmission</type>
    <joint name="mico_joint_finger_2">
      <hardwareInterface>EffortJointInterface</hardwareInterface>
    </joint>
    <actuator name="mico_joint_finger_2_actuator">
      <hardwareInterface>EffortJointInterface</hardwareInterface>
      <mechanicalReduction>1</mechanicalReduction>
    </actuator>
  </transmission>
  <link name="mico_link_finger_tip_2">
    <visual>
      <geometry>
        <mesh filename="package://mico_description/meshes/finger_distal.dae"/>
      </geometry>
      <material name="carbon_fiber">
        <color rgba="0.792156862745098 0.819607843137255 0.933333333333333 1"/>
      </material>
    </visual>
    <!-- Adding ring to the model -->
    <collision>
      <geometry>
        <mesh filename="package://mico_description/meshes/finger_distal.dae"/>
      </geometry>
    </collision>
    <!-- base = 0 -->
    <!-- shoulder = 1 -->
    <!-- arm = 2-->
    <!-- forearm = 3 -->
    <!-- wrist = 4 -->
    <!--arm_mico       		5 -->
    <!--   arm_half1 (7dof)		6 -->
    <!--   arm_half2 (7dof)		7 -->
    <!--   wrist_spherical_1  8 -->
    <!--   wrist_spherical_2  9 -->
    <!--   forearm_mico  10 -->
    <!-- hand 3 finger = 55 -->
    <!-- hand 2 finger = 56 -->
    <!-- finger_proximal = 57 -->
    <!-- finger_distal = 58 -->
    <inertial>
      <mass value="0.01"/>
      <origin xyz="0.022 0 0"/>
      <!-- z Axis -->
      <inertia ixx="7.8999684e-07" ixy="0" ixz="0" iyy="7.8999684e-07" iyz="0" izz="8e-08"/>
      <!-- y Axis -->
      <!-- x Axis -->
    </inertial>
  </link>
  <joint name="mico_joint_finger_tip_2" type="fixed">
    <parent link="mico_link_finger_2"/>
    <child link="mico_link_finger_tip_2"/>
    <axis xyz="0 0 1"/>
    <origin rpy="0 0 0" xyz="0.044 -0.003 0"/>
    <limit effort="2000" lower="0" upper="2" velocity="1"/>
  </joint>
  <!--<xacro:mico_arm parent="base_link" xyz="0.19 0 0.17" rpy="0 ${15*PI/180} 0"/>-->
  <!-- SENSORS -->
  <!-- 
	<xacro:sensor_hokuyo_ust10lx prefix="hokuyo_base" parent="base_link">
		<origin xyz="0.0 0.0 0.33" rpy="0 0 0"/>
	</xacro:sensor_hokuyo_ust10lx>

	<xacro:sensor_axis prefix="camera" parent="base_link">
		<origin xyz="0.19 0 0.26" rpy="0 ${15*PI/180} 0"/>
	</xacro:sensor_axis>
  
	<xacro:sensor_imu_hector prefix="imu" parent="base_link" >
		<origin xyz="-0.18 0.0 0.170" rpy="0 0 0"/>
	</xacro:sensor_imu_hector>
  
	<xacro:sensor_gps prefix="gps" parent="base_link">
		<origin xyz="-0.22 0 0.275" rpy="0 0 0"/>
	</xacro:sensor_gps>
-->
</robot>

